Workbook
Name DataEntryRange: Income!$A$1:$P$23
Name IncomeK4: Income!$K$4
Name Remaining_Balance: 'Person 2 Draw-down'!$AL$7
Name Remaining_Balance: 'Person 1 Draw-down'!$AL$7

Sheet Welcome
B1: Welcome!
B4: How do I use this spreadsheet? Follow these simple steps: 1) Go to the 'Income' sheet and enter your details. If you have one, enter your partner's details. 2) Go to 'Person 1 Draw-down' sheet and enter your Year of Birth, when you would like to start your retirement and when you think it'll end. Also, enter an amount that you would like to be left at the end of your retirement, the default being £0. 3) Click the 'Calculate Pension' button and wait for the calculation to complete. Detailed draw-down amounts are now visible in the 'Person 1 Draw-down' sheet. You can view the information monthly or annually by clicking the button. This is now your first insight into what your retirement might look like. If relevant, do the same for your partner and then also view your combined picture in the 'Combined Pensions' sheet. You can refine your modelling by optionally changing your spending profile, your estimation of inflation , triple-lock and also selecting your inflation tracking mode Further details are available in these accompanying videos. Enjoy exploring your future — it's all in your hands!
B5: - Video 1 - Video 2 - Video 3
B6: Assumptions: We assume that you are drawing down from either a FAD or UFPLS drawdown SIPP at a taxable rate of 75% / 25% (taxable/taxfree) Need more here ...

Sheet Income
B1: Pensions and other income
B2: Person 1 | I2: Person 2
D3: Value | E3: Growth Rate | F3: Year | G3: Pre-retirement savings, annual | K3: Value | L3: Growth Rate | M3: Year | N3: Pre-retirement savings, annual
B4: SIPP Total | D4: 990000 | E4: 0.065 | G4: 0 | I4: SIPP Total | K4: 0 | L4: 0 | N4: 0
B6: Annuity 1 | D6: 0 | E6: NA | I6: Annuity 1 | K6: 0 | L6: NA | M6: 0
B7: Annuity 2 | D7: 0 | E7: NA | I7: Annuity 2 | K7: 0 | L7: NA
B8: Annuity 3 | D8: 0 | E8: NA | I8: Annuity 3 | K8: 0 | L8: NA
B10: Defined Benefit Pension 1 | D10: 0 | E10: NA | F10: 2026 | I10: Defined Benefit Pension 1 | K10: 7000 | L10: NA | M10: 2026
B11: Defined Benefit Pension 2 | D11: 0 | E11: NA | I11: Defined Benefit Pension 2 | K11: 3000 | L11: NA | M11: 2030
B12: Defined Benefit Pension 3 | D12: 0 | E12: NA | I12: Defined Benefit Pension 3 | K12: 0 | L12: NA
F13: Draw-down | M13: Draw-down
B14: Cash ISA | D14: 20000 | E14: 0.038 | F14: =calculateAnnualDrawdown('Person 1 Calculator'!$F$4, D14, E14, 'Person 1 Calculator'!$F$5-'Person 1 Calculator'!$F$4, G14) -> 636.62 | G14: 0 | I14: Cash ISA | K14: 20000 | L14: 0.038 | M14: =calculateAnnualDrawdown('Person 1 Calculator'!$F$4, K14, L14, 'Person 1 Calculator'!$F$5-'Person 1 Calculator'!$F$4, N14) -> 636.62 | N14: 0
B15: Stocks & Shares ISA | D15: 250000 | E15: 0.065 | F15: =calculateAnnualDrawdown('Person 1 Calculator'!$F$4, D15, E15, 'Person 1 Calculator'!$F$5-'Person 1 Calculator'!$F$4, G15) -> 8062.48 | G15: 0 | I15: Stocks & Shares ISA | K15: 200000 | L15: 0.065 | M15: =calculateAnnualDrawdown('Person 1 Calculator'!$F$4, K15, L15, 'Person 1 Calculator'!$F$5-'Person 1 Calculator'!$F$4, N15) -> 6449.99 | N15: 0
B16: Cash | D16: 50000 | E16: 0.065 | F16: =calculateAnnualDrawdown('Person 1 Calculator'!$F$4, D16, E16, 'Person 1 Calculator'!$F$5-'Person 1 Calculator'!$F$4, G16) -> 1612.5 | G16: 0 | I16: Cash | K16: 150000 | L16: 0.065 | M16: =calculateAnnualDrawdown('Person 1 Calculator'!$F$4, K16, L16, 'Person 1 Calculator'!$F$5-'Person 1 Calculator'!$F$4, N16) -> 4837.49 | N16: 0
B18: Starting rent (Net) | D18: 20000 | E18: 0.025 | I18: Starting rent (Net) | K18: 0 | L18: 0.025
B20: State Pension Eligibility @ Projected Retirement Age | F20: 1 | I20: State Pension Eligibility @ Projected Retirement Age | M20: 1
B21: State Pension @ 67 | D21: =fv('Person 1 Calculator'!$F$19,'Person 1 Calculator'!$F$7-year(today()),0,-(F20*(52*230.25))) -> 17722.965 | I21: State Pension @ 67 | K21: =fv('Person 2 Calculator'!$F$19,'Person 2 Calculator'!$F$7-year(today()),0,-(M20*(52*230.25))) -> 18431.883

Sheet Person 1 Calculator
B1: Person 1 Pension Calculator
B2: Parameters | H2: Income Performance
B3: Year of Birth | F3: 1968
B4: Start Draw-down In | F4: 2026
B5: End Draw-down By | F5: 2058
B6: Private Pension Eligible Year (age 55) | F6: =F3+55 -> 2023
B7: State Pension Eligible Year | F7: =F3+67 -> 2035
B8: Final Year Percentage (keep hidden)
B9: First Year Estimated Income | C9: Net | D9: ='Person 1 Draw-down'!G32 -> 89085.252 | E9: | Gross | F9: 108669.67
B10: Estimated Income @ 70 | C10: Net Real | D10: ='Person 1 Draw-down'!S27*$D$9 -> 71268.202 | E10: | Nominal Gross | F10: ='Person 1 Draw-down'!S24 -> 116918.9
B11: Estimated Income @ 80 | C11: Net Real | D11: ='Person 1 Draw-down'!AC27*$D$9 -> 53451.151 | E11: | Nominal Gross | F11: ='Person 1 Draw-down'!AC24 -> 112249.56
B12: Final Year Estimated Income | C12: Net Real | D12: ='Person 1 Draw-down'!AL27*$D$9 -> 53451.151 | E12: | Nominal Gross | F12: ='Person 1 Draw-down'!AL24 -> 140184.32
B13: Final Year SIPP Balance Target | F13: 0
B14: Final Year SIPP Balance | F14: ='Person 1 Draw-down'!AL6 -> 0.38076382
B16: Optional annual spending reduction from age 70 | F16: 0.2
B17: Optional annual spending reduction from age 80 | F17: 0.4
B18: Inflation | F18: 0.025
B19: State Pension Growth (triple-lock) | F19: 0.04
B20: Inflation tracking mode | F20: Smooth

Sheet Person 1 Draw-down
A1: Pension 1 Draw-down
A3: Age | D3: 55 | E3: 56 | F3: 57 | G3: 58 | H3: 59 | I3: 60 | J3: 61 | K3: 62 | L3: 63 | M3: 64 | N3: 65 | O3: 66 | P3: 67 | Q3: 68 | R3: 69 | S3: 70 | T3: 71 | U3: 72 | V3: 73 | W3: 74 | X3: 75 | Y3: 76 | Z3: 77 | AA3: 78 | AB3: 79 | AC3: 80 | AD3: 81 | AE3: 82 | AF3: 83 | AG3: 84 | AH3: 85 | AI3: 86 | AJ3: 87 | AK3: 88 | AL3: 89 | AM3: 90 | AN3: 91 | AO3: 92 | AP3: 93 | AQ3: 94 | AR3: 95 | AS3: 96 | AT3: 97 | AU3: 98 | AV3: 99
A4: Year | D4: ='Person 1 Calculator'!$F$6 -> 2023 | E4: =D4+1 -> 2024 | F4: =E4+1 -> 2025 | G4: =F4+1 -> 2026 | H4: =G4+1 -> 2027 | I4: =H4+1 -> 2028 | J4: =I4+1 -> 2029 | K4: =J4+1 -> 2030 | L4: =K4+1 -> 2031 | ... AV4: =AU4+1 -> 2067
A5: ONGOING ASSET VALUES | D5: =LET( TargetYear, D4, StartDate, 'Person 1 Calculator'!$F$4, EndDate, 'Person 1 Calculator'!$F$5, IFS( TargetYear < StartDate, 0, TargetYear = StartDate, 1, AND(TargetYear > StartDate, TargetYear < EndDate), 2, TargetYear >= EndDate, 3 ) ) -> 0 | E5: =LET( TargetYear, E4, StartDate, 'Person 1 Calculator'!$F$4, EndDate, 'Person 1 Calculator'!$F$5, IFS( TargetYear < StartDate, 0, TargetYear = StartDate, 1, AND(TargetYear > StartDate, TargetYear < EndDate), 2, TargetYear >= EndDate, 3 ) ) -> 0 | F5: =LET( TargetYear, F4, StartDate, 'Person 1 Calculator'!$F$4, EndDate, 'Person 1 Calculator'!$F$5, IFS( TargetYear < StartDate, 0, TargetYear = StartDate, 1, AND(TargetYear > StartDate, TargetYear < EndDate), 2, TargetYear >= EndDate, 3 ) ) -> 0 | G5: =LET( TargetYear, G4, StartDate, 'Person 1 Calculator'!$F$4, EndDate, 'Person 1 Calculator'!$F$5, IFS( TargetYear < StartDate, 0, TargetYear = StartDate, 1, AND(TargetYear > StartDate, TargetYear < EndDate), 2, TargetYear >= EndDate, 3 ) ) -> 1 | H5: =LET( TargetYear, H4, StartDate, 'Person 1 Calculator'!$F$4, EndDate, 'Person 1 Calculator'!$F$5, IFS( TargetYear < StartDate, 0, TargetYear = StartDate, 1, AND(TargetYear > StartDate, TargetYear < EndDate), 2, TargetYear >= EndDate, 3 ) ) -> 2 | I5: =LET( TargetYear, I4, StartDate, 'Person 1 Calculator'!$F$4, EndDate, 'Person 1 Calculator'!$F$5, IFS( TargetYear < StartDate, 0, TargetYear = StartDate, 1, AND(TargetYear > StartDate, TargetYear < EndDate), 2, TargetYear >= EndDate, 3 ) ) -> 2 | J5: =LET( TargetYear, J4, StartDate, 'Person 1 Calculator'!$F$4, EndDate, 'Person 1 Calculator'!$F$5, IFS( TargetYear < StartDate, 0, TargetYear = StartDate, 1, AND(TargetYear > StartDate, TargetYear < EndDate), 2, TargetYear >= EndDate, 3 ) ) -> 2 | K5: =LET( TargetYear, K4, StartDate, 'Person 1 Calculator'!$F$4, EndDate, 'Person 1 Calculator'!$F$5, IFS( TargetYear < StartDate, 0, TargetYear = StartDate, 1, AND(TargetYear > StartDate, TargetYear < EndDate), 2, TargetYear >= EndDate, 3 ) ) -> 2 | ... AV5: =LET( TargetYear, AV4, StartDate, 'Person 1 Calculator'!$F$4, EndDate, 'Person 1 Calculator'!$F$5, IFS( TargetYear < StartDate, 0, TargetYear = StartDate, 1, AND(TargetYear > StartDate, TargetYear < EndDate), 2, TargetYear >= EndDate, 3 ) ) -> 3
A6: SIPP Value | D6: =LET( CurrentYear, D4, PreviousYearValue, C6, ActionCode, N(D5), DeductionAmount, D7, InitialSeedValue, Income!$D$4, AnnualGrowthRate, Income!$E$4, FixedAnnualAddition, Income!$G$4, CalculationValue, IF(N(PreviousYearValue)=0, InitialSeedValue, PreviousYearValue), ProrataFactor, IF(CurrentYear = YEAR(TODAY()), (12 - MONTH(TODAY()) + 1) / 12, 1), GrowthAmount, CalculationValue * AnnualGrowthRate, IsYearInPast, CurrentYear < YEAR(TODAY()), IsStopCode, ActionCode = 3, IF(OR(IsYearInPast, IsStopCode), "", SWITCH(ActionCode, 0, CalculationValue + (GrowthAmount + FixedAnnualAddition) * ProrataFactor, 1, CalculationValue + (GrowthAmount - DeductionAmount) * ProrataFactor, 2, CalculationValue + (GrowthAmount - DeductionAmount) * ProrataFactor, "" ) ) ) | E6: =if(D6<0,D6, LET( CurrentYear, E4, PreviousYearValue, D6, ActionCode, N(E5), DeductionAmount, E7, InitialSeedValue, Income!$D$4, AnnualGrowthRate, Income!$E$4, FixedAnnualAddition, Income!$G$4, CalculationValue, IF(N(PreviousYearValue)=0, InitialSeedValue, PreviousYearValue), ProrataFactor, IF(CurrentYear = YEAR(TODAY()), (12 - MONTH(TODAY()) + 1) / 12, 1), GrowthAmount, CalculationValue * AnnualGrowthRate, IsYearInPast, CurrentYear < YEAR(TODAY()), IsStopCode, ActionCode = 3, IF(OR(IsYearInPast, IsStopCode), "", SWITCH(ActionCode, 0, CalculationValue + (GrowthAmount + FixedAnnualAddition) * ProrataFactor, 1, CalculationValue + (GrowthAmount - DeductionAmount) * ProrataFactor, 2, CalculationValue + (GrowthAmount - DeductionAmount) * ProrataFactor, "" ) ) ) ) | F6: =if(E6<0,E6, LET( CurrentYear, F4, PreviousYearValue, E6, ActionCode, N(F5), DeductionAmount, F7, InitialSeedValue, Income!$D$4, AnnualGrowthRate, Income!$E$4, FixedAnnualAddition, Income!$G$4, CalculationValue, IF(N(PreviousYearValue)=0, InitialSeedValue, PreviousYearValue), ProrataFactor, IF(CurrentYear = YEAR(TODAY()), (12 - MONTH(TODAY()) + 1) / 12, 1), GrowthAmount, CalculationValue * AnnualGrowthRate, IsYearInPast, CurrentYear < YEAR(TODAY()), IsStopCode, ActionCode = 3, IF(OR(IsYearInPast, IsStopCode), "", SWITCH(ActionCode, 0, CalculationValue + (GrowthAmount + FixedAnnualAddition) * ProrataFactor, 1, CalculationValue + (GrowthAmount - DeductionAmount) * ProrataFactor, 2, CalculationValue + (GrowthAmount - DeductionAmount) * ProrataFactor, "" ) ) ) ) -> 1000725 | G6: =if(F6<0,F6, LET( CurrentYear, G4, PreviousYearValue, F6, ActionCode, N(G5), DeductionAmount, G7, InitialSeedValue, Income!$D$4, AnnualGrowthRate, Income!$E$4, FixedAnnualAddition, Income!$G$4, CalculationValue, IF(N(PreviousYearValue)=0, InitialSeedValue, PreviousYearValue), ProrataFactor, IF(CurrentYear = YEAR(TODAY()), (12 - MONTH(TODAY()) + 1) / 12, 1), GrowthAmount, CalculationValue * AnnualGrowthRate, IsYearInPast, CurrentYear < YEAR(TODAY()), IsStopCode, ActionCode = 3, IF(OR(IsYearInPast, IsStopCode), "", SWITCH(ActionCode, 0, CalculationValue + (GrowthAmount + FixedAnnualAddition) * ProrataFactor, 1, CalculationValue + (GrowthAmount - DeductionAmount) * ProrataFactor, 2, CalculationValue + (GrowthAmount - DeductionAmount) * ProrataFactor, "" ) ) ) ) -> 987414.05 | H6: =if(G6<0,G6, LET( CurrentYear, H4, PreviousYearValue, G6, ActionCode, N(H5), DeductionAmount, H7, InitialSeedValue, Income!$D$4, AnnualGrowthRate, Income!$E$4, FixedAnnualAddition, Income!$G$4, CalculationValue, IF(N(PreviousYearValue)=0, InitialSeedValue, PreviousYearValue), ProrataFactor, IF(CurrentYear = YEAR(TODAY()), (12 - MONTH(TODAY()) + 1) / 12, 1), GrowthAmount, CalculationValue * AnnualGrowthRate, IsYearInPast, CurrentYear < YEAR(TODAY()), IsStopCode, ActionCode = 3, IF(OR(IsYearInPast, IsStopCode), "", SWITCH(ActionCode, 0, CalculationValue + (GrowthAmount + FixedAnnualAddition) * ProrataFactor, 1, CalculationValue + (GrowthAmount - DeductionAmount) * ProrataFactor, 2, CalculationValue + (GrowthAmount - DeductionAmount) * ProrataFactor, "" ) ) ) ) -> 971021.15 | I6: =if(H6<0,H6, LET( CurrentYear, I4, PreviousYearValue, H6, ActionCode, N(I5), DeductionAmount, I7, InitialSeedValue, Income!$D$4, AnnualGrowthRate, Income!$E$4, FixedAnnualAddition, Income!$G$4, CalculationValue, IF(N(PreviousYearValue)=0, InitialSeedValue, PreviousYearValue), ProrataFactor, IF(CurrentYear = YEAR(TODAY()), (12 - MONTH(TODAY()) + 1) / 12, 1), GrowthAmount, CalculationValue * AnnualGrowthRate, IsYearInPast, CurrentYear < YEAR(TODAY()), IsStopCode, ActionCode = 3, IF(OR(IsYearInPast, IsStopCode), "", SWITCH(ActionCode, 0, CalculationValue + (GrowthAmount + FixedAnnualAddition) * ProrataFactor, 1, CalculationValue + (GrowthAmount - DeductionAmount) * ProrataFactor, 2, CalculationValue + (GrowthAmount - DeductionAmount) * ProrataFactor, "" ) ) ) ) -> 951290.54 | J6: =if(I6<0,I6, LET( CurrentYear, J4, PreviousYearValue, I6, ActionCode, N(J5), DeductionAmount, J7, InitialSeedValue, Income!$D$4, AnnualGrowthRate, Income!$E$4, FixedAnnualAddition, Income!$G$4, CalculationValue, IF(N(PreviousYearValue)=0, InitialSeedValue, PreviousYearValue), ProrataFactor, IF(CurrentYear = YEAR(TODAY()), (12 - MONTH(TODAY()) + 1) / 12, 1), GrowthAmount, CalculationValue * AnnualGrowthRate, IsYearInPast, CurrentYear < YEAR(TODAY()), IsStopCode, ActionCode = 3, IF(OR(IsYearInPast, IsStopCode), "", SWITCH(ActionCode, 0, CalculationValue + (GrowthAmount + FixedAnnualAddition) * ProrataFactor, 1, CalculationValue + (GrowthAmount - DeductionAmount) * ProrataFactor, 2, CalculationValue + (GrowthAmount - DeductionAmount) * ProrataFactor, "" ) ) ) ) -> 927948.49 | K6: =if(J6<0,J6, LET( CurrentYear, K4, PreviousYearValue, J6, ActionCode, N(K5), DeductionAmount, K7, InitialSeedValue, Income!$D$4, AnnualGrowthRate, Income!$E$4, FixedAnnualAddition, Income!$G$4, CalculationValue, IF(N(PreviousYearValue)=0, InitialSeedValue, PreviousYearValue), ProrataFactor, IF(CurrentYear = YEAR(TODAY()), (12 - MONTH(TODAY()) + 1) / 12, 1), GrowthAmount, CalculationValue * AnnualGrowthRate, IsYearInPast, CurrentYear < YEAR(TODAY()), IsStopCode, ActionCode = 3, IF(OR(IsYearInPast, IsStopCode), "", SWITCH(ActionCode, 0, CalculationValue + (GrowthAmount + FixedAnnualAddition) * ProrataFactor, 1, CalculationValue + (GrowthAmount - DeductionAmount) * ProrataFactor, 2, CalculationValue + (GrowthAmount - DeductionAmount) * ProrataFactor, "" ) ) ) ) -> 900702.01 | L6: =if(K6<0,K6, LET( CurrentYear, L4, PreviousYearValue, K6, ActionCode, N(L5), DeductionAmount, L7, InitialSeedValue, Income!$D$4, AnnualGrowthRate, Income!$E$4, FixedAnnualAddition, Income!$G$4, CalculationValue, IF(N(PreviousYearValue)=0, InitialSeedValue, PreviousYearValue), ProrataFactor, IF(CurrentYear = YEAR(TODAY()), (12 - MONTH(TODAY()) + 1) / 12, 1), GrowthAmount, CalculationValue * AnnualGrowthRate, IsYearInPast, CurrentYear < YEAR(TODAY()), IsStopCode, ActionCode = 3, IF(OR(IsYearInPast, IsStopCode), "", SWITCH(ActionCode, 0, CalculationValue + (GrowthAmount + FixedAnnualAddition) * ProrataFactor, 1, CalculationValue + (GrowthAmount - DeductionAmount) * ProrataFactor, 2, CalculationValue + (GrowthAmount - DeductionAmount) * ProrataFactor, "" ) ) ) ) -> 869237.64 | ... AV6: =if(AU6<0,AU6, LET( CurrentYear, AV4, PreviousYearValue, AU6, ActionCode, N(AV5), DeductionAmount, AV7, InitialSeedValue, Income!$D$4, AnnualGrowthRate, Income!$E$4, FixedAnnualAddition, Income!$G$4, CalculationValue, IF(N(PreviousYearValue)=0, InitialSeedValue, PreviousYearValue), ProrataFactor, IF(CurrentYear = YEAR(TODAY()), (12 - MONTH(TODAY()) + 1) / 12, 1), GrowthAmount, CalculationValue * AnnualGrowthRate, IsYearInPast, CurrentYear < YEAR(TODAY()), IsStopCode, ActionCode = 3, IF(OR(IsYearInPast, IsStopCode), "", SWITCH(ActionCode, 0, CalculationValue + (GrowthAmount + FixedAnnualAddition) * ProrataFactor, 1, CalculationValue + (GrowthAmount - DeductionAmount) * ProrataFactor, 2, CalculationValue + (GrowthAmount - DeductionAmount) * ProrataFactor, "" ) ) ) )
A7: Annual SIPP Draw-down | D7: =IF(OR(D5=1, D5=2), D26-D12-D14-D16-D18-D20-D22, ) | E7: =LET( base, E26 - E12 - E14 - E16 - E18 - E20 - E22, IFS( E5 = 0, "", E5 = 1, base, E5 = 2, IF( ISNUMBER(SEARCH("Smooth", 'Person 1 Calculator'!$F$20)), MAX(base, 0), D7 ), E5 = 3, "" ) ) | F7: =LET( base, F26 - F12 - F14 - F16 - F18 - F20 - F22, IFS( F5 = 0, "", F5 = 1, base, F5 = 2, IF( ISNUMBER(SEARCH("Smooth", 'Person 1 Calculator'!$F$20)), MAX(base, 0), E7 ), F5 = 3, "" ) ) | G7: =LET( base, G26 - G12 - G14 - G16 - G18 - G20 - G22, IFS( G5 = 0, "", G5 = 1, base, G5 = 2, IF( ISNUMBER(SEARCH("Smooth", 'Person 1 Calculator'!$F$20)), MAX(base, 0), F7 ), G5 = 3, "" ) ) -> 78358.075 | H7: =LET( base, H26 - H12 - H14 - H16 - H18 - H20 - H22, IFS( H5 = 0, "", H5 = 1, base, H5 = 2, IF( ISNUMBER(SEARCH("Smooth", 'Person 1 Calculator'!$F$20)), MAX(base, 0), G7 ), H5 = 3, "" ) ) -> 80574.817 | I7: =IF(OR(I5=1, I5=2), I26-I12-I14-I16-I18-I20-I22, ) -> 82846.977 | J7: =LET( base, J26 - J12 - J14 - J16 - J18 - J20 - J22, IFS( J5 = 0, "", J5 = 1, base, J5 = 2, IF( ISNUMBER(SEARCH("Smooth", 'Person 1 Calculator'!$F$20)), MAX(base, 0), I7 ), J5 = 3, "" ) ) -> 85175.942 | K7: =LET( base, K26 - K12 - K14 - K16 - K18 - K20 - K22, IFS( K5 = 0, "", K5 = 1, base, K5 = 2, IF( ISNUMBER(SEARCH("Smooth", 'Person 1 Calculator'!$F$20)), MAX(base, 0), J7 ), K5 = 3, "" ) ) -> 87563.13 | L7: =LET( base, L26 - L12 - L14 - L16 - L18 - L20 - L22, IFS( L5 = 0, "", L5 = 1, base, L5 = 2, IF( ISNUMBER(SEARCH("Smooth", 'Person 1 Calculator'!$F$20)), MAX(base, 0), K7 ), L5 = 3, "" ) ) -> 90009.998 | M7: =LET( base, M26 - M12 - M14 - M16 - M18 - M20 - M22, IFS( M5 = 0, "", M5 = 1, base, M5 = 2, IF( ISNUMBER(SEARCH("Smooth", 'Person 1 Calculator'!$F$20)), MAX(base, 0), L7 ), M5 = 3, "" ) ) -> 92518.038 | N7: =IF(OR(N5=1, N5=2), N26-N12-N14-N16-N18-N20-N22, ) -> 95088.779 | O7: =LET( base, O26 - O12 - O14 - O16 - O18 - O20 - O22, IFS( O5 = 0, "", O5 = 1, base, O5 = 2, IF( ISNUMBER(SEARCH("Smooth", 'Person 1 Calculator'!$F$20)), MAX(base, 0), N7 ), O5 = 3, "" ) ) -> 97723.789 | P7: =LET( base, P26 - P12 - P14 - P16 - P18 - P20 - P22, raw, IFS( P5 = 0, "", P5 = 1, base, P5 = 2, IF( ISNUMBER(SEARCH("Smooth", 'Person 1 Calculator'!$F$20)), base, O7 - P16 ), P5 = 3, "" ), IF(ISNUMBER(raw), MAX(raw, 0), raw) ) -> 82701.709 | Q7: =LET( base, Q26 - Q12 - Q14 - Q16 - Q18 - Q20 - Q22, IFS( Q5 = 0, "", Q5 = 1, base, Q5 = 2, IF( ISNUMBER(SEARCH("Smooth", 'Person 1 Calculator'!$F$20)), MAX(base, 0), P7 ), Q5 = 3, "" ) ) -> 84761.197 | R7: =LET( base, R26 - R12 - R14 - R16 - R18 - R20 - R22, IFS( R5 = 0, "", R5 = 1, base, R5 = 2, IF( ISNUMBER(SEARCH("Smooth", 'Person 1 Calculator'!$F$20)), MAX(base, 0), Q7 ), R5 = 3, "" ) ) -> 86861.539 | S7: =IF( OR(S5 = 1, S5 = 2), MAX(0, (1-'Person 1 Calculator'!$F$16)*S26 - S12 - S14 - S16 - S18 - S20 - S22), "" ) -> 59773.603 | T7: =LET( base, (1-'Person 1 Calculator'!$F$16)*T26 - T12 - T14 - T16 - T18 - T20 - T22, IFS( T5 = 0, "", T5 = 1, base, T5 = 2, IF( ISNUMBER(SEARCH("Smooth", 'Person 1 Calculator'!$F$20)), MAX(base, 0), S7 ), T5 = 3, "" ) ) -> 61226.695 | U7: =LET( base, (1-'Person 1 Calculator'!$F$16)*U26 - U12 - U14 - U16 - U18 - U20 - U22, IFS( U5 = 0, "", U5 = 1, base, U5 = 2, IF( ISNUMBER(SEARCH("Smooth", 'Person 1 Calculator'!$F$20)), MAX(base, 0), T7 ), U5 = 3, "" ) ) -> 62704.152 | V7: =LET( base, (1-'Person 1 Calculator'!$F$16)*V26 - V12 - V14 - V16 - V18 - V20 - V22, IFS( V5 = 0, "", V5 = 1, base, V5 = 2, IF( ISNUMBER(SEARCH("Smooth", 'Person 1 Calculator'!$F$20)), MAX(base, 0), U7 ), V5 = 3, "" ) ) -> 64206.105 | W7: =LET( base, (1-'Person 1 Calculator'!$F$16)*W26 - W12 - W14 - W16 - W18 - W20 - W22, IFS( W5 = 0, "", W5 = 1, base, W5 = 2, IF( ISNUMBER(SEARCH("Smooth", 'Person 1 Calculator'!$F$20)), MAX(base, 0), V7 ), W5 = 3, "" ) ) -> 65732.669 | X7: =IF( OR(X5 = 1, X5 = 2), MAX(0, (1-'Person 1 Calculator'!$F$16)*X26 - X12 - X14 - X16 - X18 - X20 - X22), "" ) -> 67283.943 | Y7: =LET( base, (1-'Person 1 Calculator'!$F$16)*Y26 - Y12 - Y14 - Y16 - Y18 - Y20 - Y22, IFS( Y5 = 0, "", Y5 = 1, base, Y5 = 2, IF( ISNUMBER(SEARCH("Smooth", 'Person 1 Calculator'!$F$20)), MAX(base, 0), X7 ), Y5 = 3, "" ) ) -> 68860.005 | Z7: =LET( base, (1-'Person 1 Calculator'!$F$16)*Z26 - Z12 - Z14 - Z16 - Z18 - Z20 - Z22, IFS( Z5 = 0, "", Z5 = 1, base, Z5 = 2, IF( ISNUMBER(SEARCH("Smooth", 'Person 1 Calculator'!$F$20)), MAX(base, 0), Y7 ), Z5 = 3, "" ) ) -> 70460.916 | AA7: =LET( base, (1-'Person 1 Calculator'!$F$16)*AA26 - AA12 - AA14 - AA16 - AA18 - AA20 - AA22, IFS( AA5 = 0, "", AA5 = 1, base, AA5 = 2, IF( ISNUMBER(SEARCH("Smooth", 'Person 1 Calculator'!$F$20)), MAX(base, 0), Z7 ), AA5 = 3, "" ) ) -> 72086.714 | AB7: =LET( base, (1-'Person 1 Calculator'!$F$16)*AB26 - AB12 - AB14 - AB16 - AB18 - AB20 - AB22, IFS( AB5 = 0, "", AB5 = 1, base, AB5 = 2, IF( ISNUMBER(SEARCH("Smooth", 'Person 1 Calculator'!$F$20)), MAX(base, 0), AA7 ), AB5 = 3, "" ) ) -> 73737.416 | AC7: =IF( OR(AC5 = 1, AC5 = 2), MAX(0, (1-'Person 1 Calculator'!$F$17)*AC26 - AC12 - AC14 - AC16 - AC18 - AC20 - AC22), "" ) -> 37996.495 | AD7: =LET( base, (1-'Person 1 Calculator'!$F$17)*AD26 - AD12 - AD14 - AD16 - AD18 - AD20 - AD22, IFS( AD5 = 0, "", AD5 = 1, base, AD5 = 2, IF( ISNUMBER(SEARCH("Smooth", 'Person 1 Calculator'!$F$20)), MAX(base, 0), AC7 ), AD5 = 3, "" ) ) -> 38761.547 | AE7: =LET( base, (1-'Person 1 Calculator'!$F$17)*AE26 - AE12 - AE14 - AE16 - AE18 - AE20 - AE22, IFS( AE5 = 0, "", AE5 = 1, base, AE5 = 2, IF( ISNUMBER(SEARCH("Smooth", 'Person 1 Calculator'!$F$20)), MAX(base, 0), AD7 ), AE5 = 3, "" ) ) -> 39528.019 | AF7: =LET( base, (1-'Person 1 Calculator'!$F$17)*AF26 - AF12 - AF14 - AF16 - AF18 - AF20 - AF22, IFS( AF5 = 0, "", AF5 = 1, base, AF5 = 2, IF( ISNUMBER(SEARCH("Smooth", 'Person 1 Calculator'!$F$20)), MAX(base, 0), AE7 ), AF5 = 3, "" ) ) -> 40295.239 | AG7: =LET( base, (1-'Person 1 Calculator'!$F$17)*AG26 - AG12 - AG14 - AG16 - AG18 - AG20 - AG22, IFS( AG5 = 0, "", AG5 = 1, base, AG5 = 2, IF( ISNUMBER(SEARCH("Smooth", 'Person 1 Calculator'!$F$20)), MAX(base, 0), AF7 ), AG5 = 3, "" ) ) -> 41062.488 | AH7: =IF( OR(AH5 = 1, AH5 = 2), MAX(0, (1-'Person 1 Calculator'!$F$17)*AH26 - AH12 - AH14 - AH16 - AH18 - AH20 - AH22), "" ) -> 41829.002 | AI7: =LET( base, (1-'Person 1 Calculator'!$F$17)*AI26 - AI12 - AI14 - AI16 - AI18 - AI20 - AI22, IFS( AI5 = 0, "", AI5 = 1, base, AI5 = 2, IF( ISNUMBER(SEARCH("Smooth", 'Person 1 Calculator'!$F$20)), MAX(base, 0), AH7 ), AI5 = 3, "" ) ) -> 42593.965 | AJ7: =LET( base, (1-'Person 1 Calculator'!$F$17)*AJ26 - AJ12 - AJ14 - AJ16 - AJ18 - AJ20 - AJ22, IFS( AJ5 = 0, "", AJ5 = 1, base, AJ5 = 2, IF( ISNUMBER(SEARCH("Smooth", 'Person 1 Calculator'!$F$20)), MAX(base, 0), AI7 ), AJ5 = 3, "" ) ) -> 43356.509 | AK7: =LET( base, (1-'Person 1 Calculator'!$F$17)*AK26 - AK12 - AK14 - AK16 - AK18 - AK20 - AK22, IFS( AK5 = 0, "", AK5 = 1, base, AK5 = 2, IF( ISNUMBER(SEARCH("Smooth", 'Person 1 Calculator'!$F$20)), MAX(base, 0), AJ7 ), AK5 = 3, "" ) ) -> 44115.714 | AL7: =LET( base, (1-'Person 1 Calculator'!$F$17)*AL26 - AL12 - AL14 - AL16 - AL18 - AL20 - AL22, IFS( AL5 = 0, "", AL5 = 1, base, AL5 = 2, IF( ISNUMBER(SEARCH("Smooth", 'Person 1 Calculator'!$F$20)), MAX(base, 0), AK7 ), AL5 = 3, "" ) ) -> 44870.599 | AM7: =IF( OR(AM5 = 1, AM5 = 2), MAX(0, (1-'Person 1 Calculator'!$F$17)*AM26 - AM12 - AM14 - AM16 - AM18 - AM20 - AM22), "" ) | AN7: =LET( base, (1-'Person 1 Calculator'!$F$17)*AN26 - AN12 - AN14 - AN16 - AN18 - AN20 - AN22, IFS( AN5 = 0, "", AN5 = 1, base, AN5 = 2, IF( ISNUMBER(SEARCH("Smooth", 'Person 1 Calculator'!$F$20)), MAX(base, 0), AM7 ), AN5 = 3, "" ) ) | AO7: =LET( base, (1-'Person 1 Calculator'!$F$17)*AO26 - AO12 - AO14 - AO16 - AO18 - AO20 - AO22, IFS( AO5 = 0, "", AO5 = 1, base, AO5 = 2, IF( ISNUMBER(SEARCH("Smooth", 'Person 1 Calculator'!$F$20)), MAX(base, 0), AN7 ), AO5 = 3, "" ) ) | AP7: =LET( base, (1-'Person 1 Calculator'!$F$17)*AP26 - AP12 - AP14 - AP16 - AP18 - AP20 - AP22, IFS( AP5 = 0, "", AP5 = 1, base, AP5 = 2, IF( ISNUMBER(SEARCH("Smooth", 'Person 1 Calculator'!$F$20)), MAX(base, 0), AO7 ), AP5 = 3, "" ) ) | AQ7: =LET( base, (1-'Person 1 Calculator'!$F$17)*AQ26 - AQ12 - AQ14 - AQ16 - AQ18 - AQ20 - AQ22, IFS( AQ5 = 0, "", AQ5 = 1, base, AQ5 = 2, IF( ISNUMBER(SEARCH("Smooth", 'Person 1 Calculator'!$F$20)), MAX(base, 0), AP7 ), AQ5 = 3, "" ) ) | AR7: =IF( OR(AR5 = 1, AR5 = 2), MAX(0, (1-'Person 1 Calculator'!$F$17)*AR26 - AR12 - AR14 - AR16 - AR18 - AR20 - AR22), "" ) | AS7: =LET( base, (1-'Person 1 Calculator'!$F$17)*AS26 - AS12 - AS14 - AS16 - AS18 - AS20 - AS22, IFS( AS5 = 0, "", AS5 = 1, base, AS5 = 2, IF( ISNUMBER(SEARCH("Smooth", 'Person 1 Calculator'!$F$20)), MAX(base, 0), AR7 ), AS5 = 3, "" ) ) | AT7: =LET( base, (1-'Person 1 Calculator'!$F$17)*AT26 - AT12 - AT14 - AT16 - AT18 - AT20 - AT22, IFS( AT5 = 0, "", AT5 = 1, base, AT5 = 2, IF( ISNUMBER(SEARCH("Smooth", 'Person 1 Calculator'!$F$20)), MAX(base, 0), AS7 ), AT5 = 3, "" ) ) | AU7: =LET( base, (1-'Person 1 Calculator'!$F$17)*AU26 - AU12 - AU14 - AU16 - AU18 - AU20 - AU22, IFS( AU5 = 0, "", AU5 = 1, base, AU5 = 2, IF( ISNUMBER(SEARCH("Smooth", 'Person 1 Calculator'!$F$20)), MAX(base, 0), AT7 ), AU5 = 3, "" ) ) | AV7: =LET( base, (1-'Person 1 Calculator'!$F$17)*AV26 - AV12 - AV14 - AV16 - AV18 - AV20 - AV22, IFS( AV5 = 0, "", AV5 = 1, base, AV5 = 2, IF( ISNUMBER(SEARCH("Smooth", 'Person 1 Calculator'!$F$20)), MAX(base, 0), AU7 ), AV5 = 3, "" ) )
A8: Taxable draw-down (75%) | D8: =if(N(D7)>0,D7*0.75,) | E8: =if(N(E7)>0,E7*0.75,) | F8: =if(N(F7)>0,F7*0.75,) | G8: =if(N(G7)>0,G7*0.75,) -> 58768.556 | H8: =if(N(H7)>0,H7*0.75,) -> 60431.113 | I8: =if(N(I7)>0,I7*0.75,) -> 62135.233 | J8: =if(N(J7)>0,J7*0.75,) -> 63881.956 | K8: =if(N(K7)>0,K7*0.75,) -> 65672.348 | ... AV8: =if(N(AV7)>0,AV7*0.75,)
A9: Tax-free draw-down (25%) | D9: =if(N(D7)>0,D7*0.25,) | E9: =if(N(E7)>0,E7*0.25,) | F9: =if(N(F7)>0,F7*0.25,) | G9: =if(N(G7)>0,G7*0.25,) -> 19589.519 | H9: =if(N(H7)>0,H7*0.25,) -> 20143.704 | I9: =if(N(I7)>0,I7*0.25,) -> 20711.744 | J9: =if(N(J7)>0,J7*0.25,) -> 21293.985 | K9: =if(N(K7)>0,K7*0.25,) -> 21890.783 | ... AV9: =if(N(AV7)>0,AV7*0.25,)
A10: Accumulated tax free draw-down | D10: =D9 | E10: =if(OR(E5=1,E5=2),D10+E9,) | F10: =if(OR(F5=1,F5=2),E10+F9,) | G10: =if(OR(G5=1,G5=2),F10+G9,) -> 19589.519 | H10: =if(OR(H5=1,H5=2),G10+H9,) -> 39733.223 | I10: =if(OR(I5=1,I5=2),H10+I9,) -> 60444.967 | J10: =if(OR(J5=1,J5=2),I10+J9,) -> 81738.953 | K10: =if(OR(K5=1,K5=2),J10+K9,) -> 103629.74 | L10: =if(OR(L5=1,L5=2),K10+L9,) -> 126132.23 | ... AV10: =if(OR(AV5=1,AV5=2),AU10+AV9,)
A11: Monthly SIPP draw-down | D11: =if(N(D7)>0,D7/12,) | E11: =if(N(E7)>0,E7/12,) | F11: =if(N(F7)>0,F7/12,) | G11: =if(N(G7)>0,G7/12,) -> 6529.8396 | H11: =if(N(H7)>0,H7/12,) -> 6714.5681 | I11: =if(N(I7)>0,I7/12,) -> 6903.9148 | J11: =if(N(J7)>0,J7/12,) -> 7097.9951 | K11: =if(N(K7)>0,K7/12,) -> 7296.9275 | ... AV11: =if(N(AV7)>0,AV7/12,)
A12: Annual ISAs draw-down | D12: =IF(OR(D5=1,D5=2), Income!$F$14+Income!$F$15,) | E12: =IF(OR(E5=1,E5=2), Income!$F$14+Income!$F$15,) | F12: =IF(OR(F5=1,F5=2), Income!$F$14+Income!$F$15,) | G12: =IF(OR(G5=1,G5=2), Income!$F$14+Income!$F$15,) -> 8699.1 | H12: =IF(OR(H5=1,H5=2), Income!$F$14+Income!$F$15,) -> 8699.1 | I12: =IF(OR(I5=1,I5=2), Income!$F$14+Income!$F$15,) -> 8699.1 | J12: =IF(OR(J5=1,J5=2), Income!$F$14+Income!$F$15,) -> 8699.1 | K12: =IF(OR(K5=1,K5=2), Income!$F$14+Income!$F$15,) -> 8699.1 | ... AV12: =IF(OR(AV5=1,AV5=2), Income!$F$14+Income!$F$15,)
A13: Monthly ISA draw-down | D13: =if(D12>0,D12/12,) | E13: =if(E12>0,E12/12,) | F13: =if(F12>0,F12/12,) | G13: =if(G12>0,G12/12,) -> 724.925 | H13: =if(H12>0,H12/12,) -> 724.925 | I13: =if(I12>0,I12/12,) -> 724.925 | J13: =if(J12>0,J12/12,) -> 724.925 | K13: =if(K12>0,K12/12,) -> 724.925 | ... AV13: =if(AV12>0,AV12/12,)
A14: Annual Rent | D14: =if(D5=0,, if(D5=1,Income!$D$18, if(D5=2,C14*(1+Income!$E$18), if(D5=3,,)))) | E14: =if(E5=0,, if(E5=1,Income!$D$18, if(E5=2,D14*(1+Income!$E$18), if(E5=3,,)))) | F14: =if(F5=0,, if(F5=1,Income!$D$18, if(F5=2,E14*(1+Income!$E$18), if(F5=3,,)))) | G14: =if(G5=0,, if(G5=1,Income!$D$18, if(G5=2,F14*(1+Income!$E$18), if(G5=3,,)))) -> 20000 | H14: =if(H5=0,, if(H5=1,Income!$D$18, if(H5=2,G14*(1+Income!$E$18), if(H5=3,,)))) -> 20500 | I14: =if(I5=0,, if(I5=1,Income!$D$18, if(I5=2,H14*(1+Income!$E$18), if(I5=3,,)))) -> 21012.5 | J14: =if(J5=0,, if(J5=1,Income!$D$18, if(J5=2,I14*(1+Income!$E$18), if(J5=3,,)))) -> 21537.812 | K14: =if(K5=0,, if(K5=1,Income!$D$18, if(K5=2,J14*(1+Income!$E$18), if(K5=3,,)))) -> 22076.258 | ... AV14: =if(AV5=0,, if(AV5=1,Income!$D$18, if(AV5=2,AU14*(1+Income!$E$18), if(AV5=3,,))))
A15: Monthly Rent | D15: =if(D14>0,D14/12,) | E15: =if(E14>0,E14/12,) | F15: =if(F14>0,F14/12,) | G15: =if(G14>0,G14/12,) -> 1666.6667 | H15: =if(H14>0,H14/12,) -> 1708.3333 | I15: =if(I14>0,I14/12,) -> 1751.0417 | J15: =if(J14>0,J14/12,) -> 1794.8177 | K15: =if(K14>0,K14/12,) -> 1839.6882 | ... AV15: =if(AV14>0,AV14/12,)
A16: Annual State Pension | P16: =Income!$D$21 -> 17722.965 | Q16: =IF(Q5<3,P16*(1+'Person 1 Calculator'!$F$19),) -> 18431.883 | R16: =IF(R5<3,Q16*(1+'Person 1 Calculator'!$F$19),) -> 19169.159 | S16: =IF(S5<3,R16*(1+'Person 1 Calculator'!$F$19),) -> 19935.925 | T16: =IF(T5<3,S16*(1+'Person 1 Calculator'!$F$19),) -> 20733.362 | U16: =IF(U5<3,T16*(1+'Person 1 Calculator'!$F$19),) -> 21562.697 | V16: =IF(V5<3,U16*(1+'Person 1 Calculator'!$F$19),) -> 22425.204 | W16: =IF(W5<3,V16*(1+'Person 1 Calculator'!$F$19),) -> 23322.213 | X16: =IF(X5<3,W16*(1+'Person 1 Calculator'!$F$19),) -> 24255.101 | ... AV16: =IF(AV5<3,AU16*(1+'Person 1 Calculator'!$F$19),)
A17: Monthly State Pension | P17: =if(P16>0,P16/12,) -> 1476.9137 | Q17: =if(Q16>0,Q16/12,) -> 1535.9903 | R17: =if(R16>0,R16/12,) -> 1597.4299 | S17: =if(S16>0,S16/12,) -> 1661.3271 | T17: =if(T16>0,T16/12,) -> 1727.7802 | U17: =if(U16>0,U16/12,) -> 1796.8914 | V17: =if(V16>0,V16/12,) -> 1868.767 | W17: =if(W16>0,W16/12,) -> 1943.5177 | ... AV17: =if(AV16>0,AV16/12,)
A18: Annual Annuities | D18: =IFERROR(__xludf.DUMMYFUNCTION("IF( OR(D5=1, D5=2), SUM( FILTER( Income!$D$6:$D$8, D4 >= Income!$F$6:$F$8 ) ) ,)"),"") | E18: =IFERROR(__xludf.DUMMYFUNCTION("IF( OR(E5=1, E5=2), SUM( FILTER( Income!$D$6:$D$8, E4 >= Income!$F$6:$F$8 ) ) ,)"),"") | F18: =IFERROR(__xludf.DUMMYFUNCTION("IF( OR(F5=1, F5=2), SUM( FILTER( Income!$D$6:$D$8, F4 >= Income!$F$6:$F$8 ) ) ,)"),"") | G18: =IFERROR(__xludf.DUMMYFUNCTION("IF( OR(G5=1, G5=2), SUM( FILTER( Income!$D$6:$D$8, G4 >= Income!$F$6:$F$8 ) ) ,)"),0.0) -> 0 | H18: =IFERROR(__xludf.DUMMYFUNCTION("IF( OR(H5=1, H5=2), SUM( FILTER( Income!$D$6:$D$8, H4 >= Income!$F$6:$F$8 ) ) ,)"),0.0) -> 0 | I18: =IFERROR(__xludf.DUMMYFUNCTION("IF( OR(I5=1, I5=2), SUM( FILTER( Income!$D$6:$D$8, I4 >= Income!$F$6:$F$8 ) ) ,)"),0.0) -> 0 | J18: =IFERROR(__xludf.DUMMYFUNCTION("IF( OR(J5=1, J5=2), SUM( FILTER( Income!$D$6:$D$8, J4 >= Income!$F$6:$F$8 ) ) ,)"),0.0) -> 0 | K18: =IFERROR(__xludf.DUMMYFUNCTION("IF( OR(K5=1, K5=2), SUM( FILTER( Income!$D$6:$D$8, K4 >= Income!$F$6:$F$8 ) ) ,)"),0.0) -> 0 | L18: =IFERROR(__xludf.DUMMYFUNCTION("IF( OR(L5=1, L5=2), SUM( FILTER( Income!$D$6:$D$8, L4 >= Income!$F$6:$F$8 ) ) ,)"),0.0) -> 0 | M18: =IFERROR(__xludf.DUMMYFUNCTION("IF( OR(M5=1, M5=2), SUM( FILTER( Income!$D$6:$D$8, M4 >= Income!$F$6:$F$8 ) ) ,)"),0.0) -> 0 | N18: =IFERROR(__xludf.DUMMYFUNCTION("IF( OR(N5=1, N5=2), SUM( FILTER( Income!$D$6:$D$8, N4 >= Income!$F$6:$F$8 ) ) ,)"),0.0) -> 0 | O18: =IFERROR(__xludf.DUMMYFUNCTION("IF( OR(O5=1, O5=2), SUM( FILTER( Income!$D$6:$D$8, O4 >= Income!$F$6:$F$8 ) ) ,)"),0.0) -> 0 | P18: =IFERROR(__xludf.DUMMYFUNCTION("IF( OR(P5=1, P5=2), SUM( FILTER( Income!$D$6:$D$8, P4 >= Income!$F$6:$F$8 ) ) ,)"),0.0) -> 0 | Q18: =IFERROR(__xludf.DUMMYFUNCTION("IF( OR(Q5=1, Q5=2), SUM( FILTER( Income!$D$6:$D$8, Q4 >= Income!$F$6:$F$8 ) ) ,)"),0.0) -> 0 | R18: =IFERROR(__xludf.DUMMYFUNCTION("IF( OR(R5=1, R5=2), SUM( FILTER( Income!$D$6:$D$8, R4 >= Income!$F$6:$F$8 ) ) ,)"),0.0) -> 0 | S18: =IFERROR(__xludf.DUMMYFUNCTION("IF( OR(S5=1, S5=2), SUM( FILTER( Income!$D$6:$D$8, S4 >= Income!$F$6:$F$8 ) ) ,)"),0.0) -> 0 | T18: =IFERROR(__xludf.DUMMYFUNCTION("IF( OR(T5=1, T5=2), SUM( FILTER( Income!$D$6:$D$8, T4 >= Income!$F$6:$F$8 ) ) ,)"),0.0) -> 0 | U18: =IFERROR(__xludf.DUMMYFUNCTION("IF( OR(U5=1, U5=2), SUM( FILTER( Income!$D$6:$D$8, U4 >= Income!$F$6:$F$8 ) ) ,)"),0.0) -> 0 | V18: =IFERROR(__xludf.DUMMYFUNCTION("IF( OR(V5=1, V5=2), SUM( FILTER( Income!$D$6:$D$8, V4 >= Income!$F$6:$F$8 ) ) ,)"),0.0) -> 0 | W18: =IFERROR(__xludf.DUMMYFUNCTION("IF( OR(W5=1, W5=2), SUM( FILTER( Income!$D$6:$D$8, W4 >= Income!$F$6:$F$8 ) ) ,)"),0.0) -> 0 | X18: =IFERROR(__xludf.DUMMYFUNCTION("IF( OR(X5=1, X5=2), SUM( FILTER( Income!$D$6:$D$8, X4 >= Income!$F$6:$F$8 ) ) ,)"),0.0) -> 0 | Y18: =IFERROR(__xludf.DUMMYFUNCTION("IF( OR(Y5=1, Y5=2), SUM( FILTER( Income!$D$6:$D$8, Y4 >= Income!$F$6:$F$8 ) ) ,)"),0.0) -> 0 | Z18: =IFERROR(__xludf.DUMMYFUNCTION("IF( OR(Z5=1, Z5=2), SUM( FILTER( Income!$D$6:$D$8, Z4 >= Income!$F$6:$F$8 ) ) ,)"),0.0) -> 0 | AA18: =IFERROR(__xludf.DUMMYFUNCTION("IF( OR(AA5=1, AA5=2), SUM( FILTER( Income!$D$6:$D$8, AA4 >= Income!$F$6:$F$8 ) ) ,)"),0.0) -> 0 | AB18: =IFERROR(__xludf.DUMMYFUNCTION("IF( OR(AB5=1, AB5=2), SUM( FILTER( Income!$D$6:$D$8, AB4 >= Income!$F$6:$F$8 ) ) ,)"),0.0) -> 0 | AC18: =IFERROR(__xludf.DUMMYFUNCTION("IF( OR(AC5=1, AC5=2), SUM( FILTER( Income!$D$6:$D$8, AC4 >= Income!$F$6:$F$8 ) ) ,)"),0.0) -> 0 | AD18: =IFERROR(__xludf.DUMMYFUNCTION("IF( OR(AD5=1, AD5=2), SUM( FILTER( Income!$D$6:$D$8, AD4 >= Income!$F$6:$F$8 ) ) ,)"),0.0) -> 0 | AE18: =IFERROR(__xludf.DUMMYFUNCTION("IF( OR(AE5=1, AE5=2), SUM( FILTER( Income!$D$6:$D$8, AE4 >= Income!$F$6:$F$8 ) ) ,)"),0.0) -> 0 | AF18: =IFERROR(__xludf.DUMMYFUNCTION("IF( OR(AF5=1, AF5=2), SUM( FILTER( Income!$D$6:$D$8, AF4 >= Income!$F$6:$F$8 ) ) ,)"),0.0) -> 0 | AG18: =IFERROR(__xludf.DUMMYFUNCTION("IF( OR(AG5=1, AG5=2), SUM( FILTER( Income!$D$6:$D$8, AG4 >= Income!$F$6:$F$8 ) ) ,)"),0.0) -> 0 | AH18: =IFERROR(__xludf.DUMMYFUNCTION("IF( OR(AH5=1, AH5=2), SUM( FILTER( Income!$D$6:$D$8, AH4 >= Income!$F$6:$F$8 ) ) ,)"),0.0) -> 0 | AI18: =IFERROR(__xludf.DUMMYFUNCTION("IF( OR(AI5=1, AI5=2), SUM( FILTER( Income!$D$6:$D$8, AI4 >= Income!$F$6:$F$8 ) ) ,)"),0.0) -> 0 | AJ18: =IFERROR(__xludf.DUMMYFUNCTION("IF( OR(AJ5=1, AJ5=2), SUM( FILTER( Income!$D$6:$D$8, AJ4 >= Income!$F$6:$F$8 ) ) ,)"),0.0) -> 0 | AK18: =IFERROR(__xludf.DUMMYFUNCTION("IF( OR(AK5=1, AK5=2), SUM( FILTER( Income!$D$6:$D$8, AK4 >= Income!$F$6:$F$8 ) ) ,)"),0.0) -> 0 | AL18: =IFERROR(__xludf.DUMMYFUNCTION("IF( OR(AL5=1, AL5=2), SUM( FILTER( Income!$D$6:$D$8, AL4 >= Income!$F$6:$F$8 ) ) ,)"),0.0) -> 0 | AM18: =IFERROR(__xludf.DUMMYFUNCTION("IF( OR(AM5=1, AM5=2), SUM( FILTER( Income!$D$6:$D$8, AM4 >= Income!$F$6:$F$8 ) ) ,)"),"") | AN18: =IFERROR(__xludf.DUMMYFUNCTION("IF( OR(AN5=1, AN5=2), SUM( FILTER( Income!$D$6:$D$8, AN4 >= Income!$F$6:$F$8 ) ) ,)"),"") | AO18: =IFERROR(__xludf.DUMMYFUNCTION("IF( OR(AO5=1, AO5=2), SUM( FILTER( Income!$D$6:$D$8, AO4 >= Income!$F$6:$F$8 ) ) ,)"),"") | AP18: =IFERROR(__xludf.DUMMYFUNCTION("IF( OR(AP5=1, AP5=2), SUM( FILTER( Income!$D$6:$D$8, AP4 >= Income!$F$6:$F$8 ) ) ,)"),"") | AQ18: =IFERROR(__xludf.DUMMYFUNCTION("IF( OR(AQ5=1, AQ5=2), SUM( FILTER( Income!$D$6:$D$8, AQ4 >= Income!$F$6:$F$8 ) ) ,)"),"") | AR18: =IFERROR(__xludf.DUMMYFUNCTION("IF( OR(AR5=1, AR5=2), SUM( FILTER( Income!$D$6:$D$8, AR4 >= Income!$F$6:$F$8 ) ) ,)"),"") | AS18: =IFERROR(__xludf.DUMMYFUNCTION("IF( OR(AS5=1, AS5=2), SUM( FILTER( Income!$D$6:$D$8, AS4 >= Income!$F$6:$F$8 ) ) ,)"),"") | AT18: =IFERROR(__xludf.DUMMYFUNCTION("IF( OR(AT5=1, AT5=2), SUM( FILTER( Income!$D$6:$D$8, AT4 >= Income!$F$6:$F$8 ) ) ,)"),"") | AU18: =IFERROR(__xludf.DUMMYFUNCTION("IF( OR(AU5=1, AU5=2), SUM( FILTER( Income!$D$6:$D$8, AU4 >= Income!$F$6:$F$8 ) ) ,)"),"") | AV18: =IFERROR(__xludf.DUMMYFUNCTION("IF( OR(AV5=1, AV5=2), SUM( FILTER( Income!$D$6:$D$8, AV4 >= Income!$F$6:$F$8 ) ) ,)"),"")
A19: Monthly Annuity | D19: =if(D18>0,D18/12,) | E19: =if(E18>0,E18/12,) | F19: =if(F18>0,F18/12,) | G19: =if(G18>0,G18/12,) | H19: =if(H18>0,H18/12,) | I19: =if(I18>0,I18/12,) | J19: =if(J18>0,J18/12,) | K19: =if(K18>0,K18/12,) | ... AV19: =if(AV18>0,AV18/12,)
A20: Annual DB Pensions | D20: =IFERROR(__xludf.DUMMYFUNCTION("IF( OR(D5=1, D5=2), SUM( FILTER( Income!$D$10:$D$12, D4 >= Income!$F$10:$F$12 ) ) ,)"),"") | E20: =IFERROR(__xludf.DUMMYFUNCTION("IF( OR(E5=1, E5=2), SUM( FILTER( Income!$D$10:$D$12, E4 >= Income!$F$10:$F$12 ) ) ,)"),"") | F20: =IFERROR(__xludf.DUMMYFUNCTION("IF( OR(F5=1, F5=2), SUM( FILTER( Income!$D$10:$D$12, F4 >= Income!$F$10:$F$12 ) ) ,)"),"") | G20: =IFERROR(__xludf.DUMMYFUNCTION("IF( OR(G5=1, G5=2), SUM( FILTER( Income!$D$10:$D$12, G4 >= Income!$F$10:$F$12 ) ) ,)"),0.0) -> 0 | H20: =IFERROR(__xludf.DUMMYFUNCTION("IF( OR(H5=1, H5=2), SUM( FILTER( Income!$D$10:$D$12, H4 >= Income!$F$10:$F$12 ) ) ,)"),0.0) -> 0 | I20: =IFERROR(__xludf.DUMMYFUNCTION("IF( OR(I5=1, I5=2), SUM( FILTER( Income!$D$10:$D$12, I4 >= Income!$F$10:$F$12 ) ) ,)"),0.0) -> 0 | J20: =IFERROR(__xludf.DUMMYFUNCTION("IF( OR(J5=1, J5=2), SUM( FILTER( Income!$D$10:$D$12, J4 >= Income!$F$10:$F$12 ) ) ,)"),0.0) -> 0 | K20: =IFERROR(__xludf.DUMMYFUNCTION("IF( OR(K5=1, K5=2), SUM( FILTER( Income!$D$10:$D$12, K4 >= Income!$F$10:$F$12 ) ) ,)"),0.0) -> 0 | L20: =IFERROR(__xludf.DUMMYFUNCTION("IF( OR(L5=1, L5=2), SUM( FILTER( Income!$D$10:$D$12, L4 >= Income!$F$10:$F$12 ) ) ,)"),0.0) -> 0 | M20: =IFERROR(__xludf.DUMMYFUNCTION("IF( OR(M5=1, M5=2), SUM( FILTER( Income!$D$10:$D$12, M4 >= Income!$F$10:$F$12 ) ) ,)"),0.0) -> 0 | N20: =IFERROR(__xludf.DUMMYFUNCTION("IF( OR(N5=1, N5=2), SUM( FILTER( Income!$D$10:$D$12, N4 >= Income!$F$10:$F$12 ) ) ,)"),0.0) -> 0 | O20: =IFERROR(__xludf.DUMMYFUNCTION("IF( OR(O5=1, O5=2), SUM( FILTER( Income!$D$10:$D$12, O4 >= Income!$F$10:$F$12 ) ) ,)"),0.0) -> 0 | P20: =IFERROR(__xludf.DUMMYFUNCTION("IF( OR(P5=1, P5=2), SUM( FILTER( Income!$D$10:$D$12, P4 >= Income!$F$10:$F$12 ) ) ,)"),0.0) -> 0 | Q20: =IFERROR(__xludf.DUMMYFUNCTION("IF( OR(Q5=1, Q5=2), SUM( FILTER( Income!$D$10:$D$12, Q4 >= Income!$F$10:$F$12 ) ) ,)"),0.0) -> 0 | R20: =IFERROR(__xludf.DUMMYFUNCTION("IF( OR(R5=1, R5=2), SUM( FILTER( Income!$D$10:$D$12, R4 >= Income!$F$10:$F$12 ) ) ,)"),0.0) -> 0 | S20: =IFERROR(__xludf.DUMMYFUNCTION("IF( OR(S5=1, S5=2), SUM( FILTER( Income!$D$10:$D$12, S4 >= Income!$F$10:$F$12 ) ) ,)"),0.0) -> 0 | T20: =IFERROR(__xludf.DUMMYFUNCTION("IF( OR(T5=1, T5=2), SUM( FILTER( Income!$D$10:$D$12, T4 >= Income!$F$10:$F$12 ) ) ,)"),0.0) -> 0 | U20: =IFERROR(__xludf.DUMMYFUNCTION("IF( OR(U5=1, U5=2), SUM( FILTER( Income!$D$10:$D$12, U4 >= Income!$F$10:$F$12 ) ) ,)"),0.0) -> 0 | V20: =IFERROR(__xludf.DUMMYFUNCTION("IF( OR(V5=1, V5=2), SUM( FILTER( Income!$D$10:$D$12, V4 >= Income!$F$10:$F$12 ) ) ,)"),0.0) -> 0 | W20: =IFERROR(__xludf.DUMMYFUNCTION("IF( OR(W5=1, W5=2), SUM( FILTER( Income!$D$10:$D$12, W4 >= Income!$F$10:$F$12 ) ) ,)"),0.0) -> 0 | X20: =IFERROR(__xludf.DUMMYFUNCTION("IF( OR(X5=1, X5=2), SUM( FILTER( Income!$D$10:$D$12, X4 >= Income!$F$10:$F$12 ) ) ,)"),0.0) -> 0 | Y20: =IFERROR(__xludf.DUMMYFUNCTION("IF( OR(Y5=1, Y5=2), SUM( FILTER( Income!$D$10:$D$12, Y4 >= Income!$F$10:$F$12 ) ) ,)"),0.0) -> 0 | Z20: =IFERROR(__xludf.DUMMYFUNCTION("IF( OR(Z5=1, Z5=2), SUM( FILTER( Income!$D$10:$D$12, Z4 >= Income!$F$10:$F$12 ) ) ,)"),0.0) -> 0 | AA20: =IFERROR(__xludf.DUMMYFUNCTION("IF( OR(AA5=1, AA5=2), SUM( FILTER( Income!$D$10:$D$12, AA4 >= Income!$F$10:$F$12 ) ) ,)"),0.0) -> 0 | AB20: =IFERROR(__xludf.DUMMYFUNCTION("IF( OR(AB5=1, AB5=2), SUM( FILTER( Income!$D$10:$D$12, AB4 >= Income!$F$10:$F$12 ) ) ,)"),0.0) -> 0 | AC20: =IFERROR(__xludf.DUMMYFUNCTION("IF( OR(AC5=1, AC5=2), SUM( FILTER( Income!$D$10:$D$12, AC4 >= Income!$F$10:$F$12 ) ) ,)"),0.0) -> 0 | AD20: =IFERROR(__xludf.DUMMYFUNCTION("IF( OR(AD5=1, AD5=2), SUM( FILTER( Income!$D$10:$D$12, AD4 >= Income!$F$10:$F$12 ) ) ,)"),0.0) -> 0 | AE20: =IFERROR(__xludf.DUMMYFUNCTION("IF( OR(AE5=1, AE5=2), SUM( FILTER( Income!$D$10:$D$12, AE4 >= Income!$F$10:$F$12 ) ) ,)"),0.0) -> 0 | AF20: =IFERROR(__xludf.DUMMYFUNCTION("IF( OR(AF5=1, AF5=2), SUM( FILTER( Income!$D$10:$D$12, AF4 >= Income!$F$10:$F$12 ) ) ,)"),0.0) -> 0 | AG20: =IFERROR(__xludf.DUMMYFUNCTION("IF( OR(AG5=1, AG5=2), SUM( FILTER( Income!$D$10:$D$12, AG4 >= Income!$F$10:$F$12 ) ) ,)"),0.0) -> 0 | AH20: =IFERROR(__xludf.DUMMYFUNCTION("IF( OR(AH5=1, AH5=2), SUM( FILTER( Income!$D$10:$D$12, AH4 >= Income!$F$10:$F$12 ) ) ,)"),0.0) -> 0 | AI20: =IFERROR(__xludf.DUMMYFUNCTION("IF( OR(AI5=1, AI5=2), SUM( FILTER( Income!$D$10:$D$12, AI4 >= Income!$F$10:$F$12 ) ) ,)"),0.0) -> 0 | AJ20: =IFERROR(__xludf.DUMMYFUNCTION("IF( OR(AJ5=1, AJ5=2), SUM( FILTER( Income!$D$10:$D$12, AJ4 >= Income!$F$10:$F$12 ) ) ,)"),0.0) -> 0 | AK20: =IFERROR(__xludf.DUMMYFUNCTION("IF( OR(AK5=1, AK5=2), SUM( FILTER( Income!$D$10:$D$12, AK4 >= Income!$F$10:$F$12 ) ) ,)"),0.0) -> 0 | AL20: =IFERROR(__xludf.DUMMYFUNCTION("IF( OR(AL5=1, AL5=2), SUM( FILTER( Income!$D$10:$D$12, AL4 >= Income!$F$10:$F$12 ) ) ,)"),0.0) -> 0 | AM20: =IFERROR(__xludf.DUMMYFUNCTION("IF( OR(AM5=1, AM5=2), SUM( FILTER( Income!$D$10:$D$12, AM4 >= Income!$F$10:$F$12 ) ) ,)"),"") | AN20: =IFERROR(__xludf.DUMMYFUNCTION("IF( OR(AN5=1, AN5=2), SUM( FILTER( Income!$D$10:$D$12, AN4 >= Income!$F$10:$F$12 ) ) ,)"),"") | AO20: =IFERROR(__xludf.DUMMYFUNCTION("IF( OR(AO5=1, AO5=2), SUM( FILTER( Income!$D$10:$D$12, AO4 >= Income!$F$10:$F$12 ) ) ,)"),"") | AP20: =IFERROR(__xludf.DUMMYFUNCTION("IF( OR(AP5=1, AP5=2), SUM( FILTER( Income!$D$10:$D$12, AP4 >= Income!$F$10:$F$12 ) ) ,)"),"") | AQ20: =IFERROR(__xludf.DUMMYFUNCTION("IF( OR(AQ5=1, AQ5=2), SUM( FILTER( Income!$D$10:$D$12, AQ4 >= Income!$F$10:$F$12 ) ) ,)"),"") | AR20: =IFERROR(__xludf.DUMMYFUNCTION("IF( OR(AR5=1, AR5=2), SUM( FILTER( Income!$D$10:$D$12, AR4 >= Income!$F$10:$F$12 ) ) ,)"),"") | AS20: =IFERROR(__xludf.DUMMYFUNCTION("IF( OR(AS5=1, AS5=2), SUM( FILTER( Income!$D$10:$D$12, AS4 >= Income!$F$10:$F$12 ) ) ,)"),"") | AT20: =IFERROR(__xludf.DUMMYFUNCTION("IF( OR(AT5=1, AT5=2), SUM( FILTER( Income!$D$10:$D$12, AT4 >= Income!$F$10:$F$12 ) ) ,)"),"") | AU20: =IFERROR(__xludf.DUMMYFUNCTION("IF( OR(AU5=1, AU5=2), SUM( FILTER( Income!$D$10:$D$12, AU4 >= Income!$F$10:$F$12 ) ) ,)"),"") | AV20: =IFERROR(__xludf.DUMMYFUNCTION("IF( OR(AV5=1, AV5=2), SUM( FILTER( Income!$D$10:$D$12, AV4 >= Income!$F$10:$F$12 ) ) ,)"),"")
A21: Monthly DB Pension | D21: =if(D20>0,D20/12,) | E21: =if(E20>0,E20/12,) | F21: =if(F20>0,F20/12,) | G21: =if(G20>0,G20/12,) | H21: =if(H20>0,H20/12,) | I21: =if(I20>0,I20/12,) | J21: =if(J20>0,J20/12,) | K21: =if(K20>0,K20/12,) | ... AV21: =if(AV20>0,AV20/12,)
A22: Annual Cash | D22: =IF( OR(D5=1, D5=2),Income!$F$16 ,) | E22: =IF( OR(E5=1, E5=2),Income!$F$16 ,) | F22: =IF( OR(F5=1, F5=2),Income!$F$16 ,) | G22: =IF( OR(G5=1, G5=2),Income!$F$16 ,) -> 1612.5 | H22: =IF( OR(H5=1, H5=2),Income!$F$16 ,) -> 1612.5 | I22: =IF( OR(I5=1, I5=2),Income!$F$16 ,) -> 1612.5 | J22: =IF( OR(J5=1, J5=2),Income!$F$16 ,) -> 1612.5 | K22: =IF( OR(K5=1, K5=2),Income!$F$16 ,) -> 1612.5 | ... AV22: =IF( OR(AV5=1, AV5=2),Income!$F$16 ,)
A23: Monthly Cash | D23: =if(D22>0, D22 / 12,) | E23: =if(E22>0, E22 / 12,) | F23: =if(F22>0, F22 / 12,) | G23: =if(G22>0, G22 / 12,) -> 134.375 | H23: =if(H22>0, H22 / 12,) -> 134.375 | I23: =if(I22>0, I22 / 12,) -> 134.375 | J23: =if(J22>0, J22 / 12,) -> 134.375 | K23: =if(K22>0, K22 / 12,) -> 134.375 | ... AV23: =if(AV22>0, AV22 / 12,)
A24: Total Annual Income | D24: =IF( D5=0,, if( D5=1, 'Person 1 Calculator'!$F$9, if(D5=2, D7+D12+D14+D16+D18+D20+D22,if(D5=3,) ))) | E24: =IF( E5=0,, if( E5=1, 'Person 1 Calculator'!$F$9, if(E5=2, E7+E12+E14+E16+E18+E20+E22,if(E5=3,) ))) | F24: =IF( F5=0,, if( F5=1, 'Person 1 Calculator'!$F$9, if(F5=2, F7+F12+F14+F16+F18+F20+F22,if(F5=3,) ))) | G24: =IF( G5=0,, if( G5=1, 'Person 1 Calculator'!$F$9, if(G5=2, G7+G12+G14+G16+G18+G20+G22,if(G5=3,) ))) -> 108669.67 | H24: =IF( H5=0,, if( H5=1, 'Person 1 Calculator'!$F$9, if(H5=2, H7+H12+H14+H16+H18+H20+H22,if(H5=3,) ))) -> 111386.42 | I24: =IF( I5=0,, if( I5=1, 'Person 1 Calculator'!$F$9, if(I5=2, I7+I12+I14+I16+I18+I20+I22,if(I5=3,) ))) -> 114171.08 | J24: =IF( J5=0,, if( J5=1, 'Person 1 Calculator'!$F$9, if(J5=2, J7+J12+J14+J16+J18+J20+J22,if(J5=3,) ))) -> 117025.35 | K24: =IF( K5=0,, if( K5=1, 'Person 1 Calculator'!$F$9, if(K5=2, K7+K12+K14+K16+K18+K20+K22,if(K5=3,) ))) -> 119950.99 | ... AV24: =IF( AV5=0,, if( AV5=1, 'Person 1 Calculator'!$F$9, if(AV5=2, AV7+AV12+AV14+AV16+AV18+AV20+AV22,if(AV5=3,) )))
A25: Total Monthly Income | D25: =if(D24>0,D24/12,) | E25: =if(E24>0,E24/12,) | F25: =if(F24>0,F24/12,) | G25: =if(G24>0,G24/12,) -> 9055.8062 | H25: =if(H24>0,H24/12,) -> 9282.2014 | I25: =if(I24>0,I24/12,) -> 9514.2564 | J25: =if(J24>0,J24/12,) -> 9752.1128 | K25: =if(K24>0,K24/12,) -> 9995.9157 | ... AV25: =if(AV24>0,AV24/12,)
A26: =concatenate("Target income with inflation of ",text('Person 1 Calculator'!F18,"0.0%")) -> Target income with inflation of 2.5% | D26: =if(D5=0,, if( D5=1, D24,if(D5=2,C26*(1+'Person 1 Calculator'!$F$18),if(D5=3,)))) | E26: =if(E5=0,, if( E5=1, E24,if(E5=2,D26*(1+'Person 1 Calculator'!$F$18),if(E5=3,)))) | F26: =if(F5=0,, if( F5=1, F24,if(F5=2,E26*(1+'Person 1 Calculator'!$F$18),if(F5=3,)))) | G26: =if(G5=0,, if( G5=1, G24,if(G5=2,F26*(1+'Person 1 Calculator'!$F$18),if(G5=3,)))) -> 108669.67 | H26: =if(H5=0,, if( H5=1, H24,if(H5=2,G26*(1+'Person 1 Calculator'!$F$18),if(H5=3,)))) -> 111386.42 | I26: =if(I5=0,, if( I5=1, I24,if(I5=2,H26*(1+'Person 1 Calculator'!$F$18),if(I5=3,)))) -> 114171.08 | J26: =if(J5=0,, if( J5=1, J24,if(J5=2,I26*(1+'Person 1 Calculator'!$F$18),if(J5=3,)))) -> 117025.35 | K26: =if(K5=0,, if( K5=1, K24,if(K5=2,J26*(1+'Person 1 Calculator'!$F$18),if(K5=3,)))) -> 119950.99 | ... AV26: =if(AV5=0,, if( AV5=1, AV24,if(AV5=2,AU26*(1+'Person 1 Calculator'!$F$18),if(AV5=3,))))
A27: Performance against inflation | D27: =if(AND(D24>0, D26>0),D24/D26,) | E27: =if(AND(E24>0, E26>0),E24/E26,) | F27: =if(AND(F24>0, F26>0),F24/F26,) | G27: =if(AND(G24>0, G26>0),G24/G26,) -> 1 | H27: =if(AND(H24>0, H26>0),H24/H26,) -> 1 | I27: =if(AND(I24>0, I26>0),I24/I26,) -> 1 | J27: =if(AND(J24>0, J26>0),J24/J26,) -> 1 | K27: =if(AND(K24>0, K26>0),K24/K26,) -> 1 | ... AV27: =if(AND(AV24>0, AV26>0),AV24/AV26,)
A28: Annual SIPP Draw-down Rate | D28: =if(D6>D7,D7/D6,) | E28: =if(E6>E7,E7/E6,) | F28: =if(F6>F7,F7/F6,) | G28: =if(G6>G7,G7/G6,) -> 0.079356856 | H28: =if(H6>H7,H7/H6,) -> 0.082979467 | I28: =if(I6>I7,I7/I6,) -> 0.087089037 | J28: =if(J6>J7,J7/J6,) -> 0.091789515 | K28: =if(K6>K7,K7/K6,) -> 0.097216537 | ... AV28: =if(AV6>AV7,AV7/AV6,)
A29: Taxable income | D29: =if(D24=0,,(if(AND(D24>0,D10<268275), D8+D14+D16+D18+D20+D22,if(D10>268275,D8+D9+D14+D16+D18+D20+D22)))) | E29: =if(E24=0,,(if(AND(E24>0,E10<268275), E8+E14+E16+E18+E20+E22,if(E10>268275,E8+E9+E14+E16+E18+E20+E22)))) | F29: =if(F24=0,,(if(AND(F24>0,F10<268275), F8+F14+F16+F18+F20+F22,if(F10>268275,F8+F9+F14+F16+F18+F20+F22)))) | G29: =if(G24=0,,(if(AND(G24>0,G10<268275), G8+G14+G16+G18+G20+G22,if(G10>268275,G8+G9+G14+G16+G18+G20+G22)))) -> 80381.056 | H29: =if(H24=0,,(if(AND(H24>0,H10<268275), H8+H14+H16+H18+H20+H22,if(H10>268275,H8+H9+H14+H16+H18+H20+H22)))) -> 82543.613 | I29: =if(I24=0,,(if(AND(I24>0,I10<268275), I8+I14+I16+I18+I20+I22,if(I10>268275,I8+I9+I14+I16+I18+I20+I22)))) -> 84760.233 | J29: =if(J24=0,,(if(AND(J24>0,J10<268275), J8+J14+J16+J18+J20+J22,if(J10>268275,J8+J9+J14+J16+J18+J20+J22)))) -> 87032.269 | K29: =if(K24=0,,(if(AND(K24>0,K10<268275), K8+K14+K16+K18+K20+K22,if(K10>268275,K8+K9+K14+K16+K18+K20+K22)))) -> 89361.105 | ... AV29: =if(AV24=0,,(if(AND(AV24>0,AV10<268275), AV8+AV14+AV16+AV18+AV20+AV22,if(AV10>268275,AV8+AV9+AV14+AV16+AV18+AV20+AV22))))
A30: Tax | D30: =LET( Income, D29, PA_Limit, 12570, BR_Limit, 50270, HR_Limit, 125140, Taper_Start, 100000, Tapered_PA, MAX(0, PA_Limit - MAX(0, (Income - Taper_Start) / 2)), TaxableIncome, MAX(0, Income - Tapered_PA), BasicRateTax, MAX(0, MIN(TaxableIncome, BR_Limit - PA_Limit)) * 0.2, HigherRateBandWidth, HR_Limit - BR_Limit, HigherRateTax, MAX(0, MIN(TaxableIncome - (BR_Limit - PA_Limit), HigherRateBandWidth)) * 0.4, AdditionalRateTax, MAX(0, TaxableIncome - (HR_Limit - PA_Limit)) * 0.45, TotalTax, BasicRateTax + HigherRateTax + AdditionalRateTax, IF(OR(ISBLANK(Income), Income = 0), "", TotalTax) ) | E30: =LET( Income, E29, PA_Limit, 12570, BR_Limit, 50270, HR_Limit, 125140, Taper_Start, 100000, Tapered_PA, MAX(0, PA_Limit - MAX(0, (Income - Taper_Start) / 2)), TaxableIncome, MAX(0, Income - Tapered_PA), BasicRateTax, MAX(0, MIN(TaxableIncome, BR_Limit - PA_Limit)) * 0.2, HigherRateBandWidth, HR_Limit - BR_Limit, HigherRateTax, MAX(0, MIN(TaxableIncome - (BR_Limit - PA_Limit), HigherRateBandWidth)) * 0.4, AdditionalRateTax, MAX(0, TaxableIncome - (HR_Limit - PA_Limit)) * 0.45, TotalTax, BasicRateTax + HigherRateTax + AdditionalRateTax, IF(OR(ISBLANK(Income), Income = 0), "", TotalTax) ) | F30: =LET( Income, F29, PA_Limit, 12570, BR_Limit, 50270, HR_Limit, 125140, Taper_Start, 100000, Tapered_PA, MAX(0, PA_Limit - MAX(0, (Income - Taper_Start) / 2)), TaxableIncome, MAX(0, Income - Tapered_PA), BasicRateTax, MAX(0, MIN(TaxableIncome, BR_Limit - PA_Limit)) * 0.2, HigherRateBandWidth, HR_Limit - BR_Limit, HigherRateTax, MAX(0, MIN(TaxableIncome - (BR_Limit - PA_Limit), HigherRateBandWidth)) * 0.4, AdditionalRateTax, MAX(0, TaxableIncome - (HR_Limit - PA_Limit)) * 0.45, TotalTax, BasicRateTax + HigherRateTax + AdditionalRateTax, IF(OR(ISBLANK(Income), Income = 0), "", TotalTax) ) | G30: =LET( Income, G29, PA_Limit, 12570, BR_Limit, 50270, HR_Limit, 125140, Taper_Start, 100000, Tapered_PA, MAX(0, PA_Limit - MAX(0, (Income - Taper_Start) / 2)), TaxableIncome, MAX(0, Income - Tapered_PA), BasicRateTax, MAX(0, MIN(TaxableIncome, BR_Limit - PA_Limit)) * 0.2, HigherRateBandWidth, HR_Limit - BR_Limit, HigherRateTax, MAX(0, MIN(TaxableIncome - (BR_Limit - PA_Limit), HigherRateBandWidth)) * 0.4, AdditionalRateTax, MAX(0, TaxableIncome - (HR_Limit - PA_Limit)) * 0.45, TotalTax, BasicRateTax + HigherRateTax + AdditionalRateTax, IF(OR(ISBLANK(Income), Income = 0), "", TotalTax) ) -> 19584.422 | H30: =LET( Income, H29, PA_Limit, 12570, BR_Limit, 50270, HR_Limit, 125140, Taper_Start, 100000, Tapered_PA, MAX(0, PA_Limit - MAX(0, (Income - Taper_Start) / 2)), TaxableIncome, MAX(0, Income - Tapered_PA), BasicRateTax, MAX(0, MIN(TaxableIncome, BR_Limit - PA_Limit)) * 0.2, HigherRateBandWidth, HR_Limit - BR_Limit, HigherRateTax, MAX(0, MIN(TaxableIncome - (BR_Limit - PA_Limit), HigherRateBandWidth)) * 0.4, AdditionalRateTax, MAX(0, TaxableIncome - (HR_Limit - PA_Limit)) * 0.45, TotalTax, BasicRateTax + HigherRateTax + AdditionalRateTax, IF(OR(ISBLANK(Income), Income = 0), "", TotalTax) ) -> 20449.445 | I30: =LET( Income, I29, PA_Limit, 12570, BR_Limit, 50270, HR_Limit, 125140, Taper_Start, 100000, Tapered_PA, MAX(0, PA_Limit - MAX(0, (Income - Taper_Start) / 2)), TaxableIncome, MAX(0, Income - Tapered_PA), BasicRateTax, MAX(0, MIN(TaxableIncome, BR_Limit - PA_Limit)) * 0.2, HigherRateBandWidth, HR_Limit - BR_Limit, HigherRateTax, MAX(0, MIN(TaxableIncome - (BR_Limit - PA_Limit), HigherRateBandWidth)) * 0.4, AdditionalRateTax, MAX(0, TaxableIncome - (HR_Limit - PA_Limit)) * 0.45, TotalTax, BasicRateTax + HigherRateTax + AdditionalRateTax, IF(OR(ISBLANK(Income), Income = 0), "", TotalTax) ) -> 21336.093 | J30: =LET( Income, J29, PA_Limit, 12570, BR_Limit, 50270, HR_Limit, 125140, Taper_Start, 100000, Tapered_PA, MAX(0, PA_Limit - MAX(0, (Income - Taper_Start) / 2)), TaxableIncome, MAX(0, Income - Tapered_PA), BasicRateTax, MAX(0, MIN(TaxableIncome, BR_Limit - PA_Limit)) * 0.2, HigherRateBandWidth, HR_Limit - BR_Limit, HigherRateTax, MAX(0, MIN(TaxableIncome - (BR_Limit - PA_Limit), HigherRateBandWidth)) * 0.4, AdditionalRateTax, MAX(0, TaxableIncome - (HR_Limit - PA_Limit)) * 0.45, TotalTax, BasicRateTax + HigherRateTax + AdditionalRateTax, IF(OR(ISBLANK(Income), Income = 0), "", TotalTax) ) -> 22244.907 | K30: =LET( Income, K29, PA_Limit, 12570, BR_Limit, 50270, HR_Limit, 125140, Taper_Start, 100000, Tapered_PA, MAX(0, PA_Limit - MAX(0, (Income - Taper_Start) / 2)), TaxableIncome, MAX(0, Income - Tapered_PA), BasicRateTax, MAX(0, MIN(TaxableIncome, BR_Limit - PA_Limit)) * 0.2, HigherRateBandWidth, HR_Limit - BR_Limit, HigherRateTax, MAX(0, MIN(TaxableIncome - (BR_Limit - PA_Limit), HigherRateBandWidth)) * 0.4, AdditionalRateTax, MAX(0, TaxableIncome - (HR_Limit - PA_Limit)) * 0.45, TotalTax, BasicRateTax + HigherRateTax + AdditionalRateTax, IF(OR(ISBLANK(Income), Income = 0), "", TotalTax) ) -> 23176.442 | ... AV30: =LET( Income, AV29, PA_Limit, 12570, BR_Limit, 50270, HR_Limit, 125140, Taper_Start, 100000, Tapered_PA, MAX(0, PA_Limit - MAX(0, (Income - Taper_Start) / 2)), TaxableIncome, MAX(0, Income - Tapered_PA), BasicRateTax, MAX(0, MIN(TaxableIncome, BR_Limit - PA_Limit)) * 0.2, HigherRateBandWidth, HR_Limit - BR_Limit, HigherRateTax, MAX(0, MIN(TaxableIncome - (BR_Limit - PA_Limit), HigherRateBandWidth)) * 0.4, AdditionalRateTax, MAX(0, TaxableIncome - (HR_Limit - PA_Limit)) * 0.45, TotalTax, BasicRateTax + HigherRateTax + AdditionalRateTax, IF(OR(ISBLANK(Income), Income = 0), "", TotalTax) )
A31: Effective tax rate | D31: =if(AND(D30>0, D24>0),D30/D24,) | E31: =if(AND(E30>0, E24>0),E30/E24,) | F31: =if(AND(F30>0, F24>0),F30/F24,) | G31: =if(AND(G30>0, G24>0),G30/G24,) -> 0.18021976 | H31: =if(AND(H30>0, H24>0),H30/H24,) -> 0.18359011 | I31: =if(AND(I30>0, I24>0),I30/I24,) -> 0.18687827 | J31: =if(AND(J30>0, J24>0),J30/J24,) -> 0.19008622 | K31: =if(AND(K30>0, K24>0),K30/K24,) -> 0.19321593 | ... AV31: =if(AND(AV30>0, AV24>0),AV30/AV24,)
A32: Total Net Income | D32: =if(D24>0,D24-D30,) | E32: =if(E24>0,E24-E30,) | F32: =if(F24>0,F24-F30,) | G32: =if(G24>0,G24-G30,) -> 89085.252 | H32: =if(H24>0,H24-H30,) -> 90936.972 | I32: =if(I24>0,I24-I30,) -> 92834.984 | J32: =if(J24>0,J24-J30,) -> 94780.447 | K32: =if(K24>0,K24-K30,) -> 96774.546 | ... AV32: =if(AV24>0,AV24-AV30,)
A33: Net Income Monthly | D33: =if(D32>0,D32/12,) | E33: =if(E32>0,E32/12,) | F33: =if(F32>0,F32/12,) | G33: =if(G32>0,G32/12,) -> 7423.771 | H33: =if(H32>0,H32/12,) -> 7578.081 | I33: =if(I32>0,I32/12,) -> 7736.2487 | J33: =if(J32>0,J32/12,) -> 7898.3706 | K33: =if(K32>0,K32/12,) -> 8064.5455 | ... AV33: =if(AV32>0,AV32/12,)
A34: NPV | D34: =if(OR(D5=1,D5=2),D27*'Person 1 Calculator'!$F$9,) | E34: =if(OR(E5=1,E5=2),E27*'Person 1 Calculator'!$F$9,) | F34: =if(OR(F5=1,F5=2),F27*'Person 1 Calculator'!$F$9,) | G34: =if(OR(G5=1,G5=2),G27*'Person 1 Calculator'!$F$9,) -> 108669.67 | H34: =if(OR(H5=1,H5=2),H27*'Person 1 Calculator'!$F$9,) -> 108669.67 | I34: =if(OR(I5=1,I5=2),I27*'Person 1 Calculator'!$F$9,) -> 108669.67 | J34: =if(OR(J5=1,J5=2),J27*'Person 1 Calculator'!$F$9,) -> 108669.67 | K34: =if(OR(K5=1,K5=2),K27*'Person 1 Calculator'!$F$9,) -> 108669.67 | ... AV34: =if(OR(AV5=1,AV5=2),AV27*'Person 1 Calculator'!$F$9,)
A35: Net NPV | D35: =if(OR(D5=1,D5=2),D27*'Person 1 Calculator'!$D$9,) | E35: =if(OR(E5=1,E5=2),E27*'Person 1 Calculator'!$D$9,) | F35: =if(OR(F5=1,F5=2),F27*'Person 1 Calculator'!$D$9,) | G35: =if(OR(G5=1,G5=2),G27*'Person 1 Calculator'!$D$9,) -> 89085.252 | H35: =if(OR(H5=1,H5=2),H27*'Person 1 Calculator'!$D$9,) -> 89085.252 | I35: =if(OR(I5=1,I5=2),I27*'Person 1 Calculator'!$D$9,) -> 89085.252 | J35: =if(OR(J5=1,J5=2),J27*'Person 1 Calculator'!$D$9,) -> 89085.252 | K35: =if(OR(K5=1,K5=2),K27*'Person 1 Calculator'!$D$9,) -> 89085.252 | ... AV35: =if(OR(AV5=1,AV5=2),AV27*'Person 1 Calculator'!$D$9,)

Sheet Person 2 Calculator
B1: Person 2 Pension Calculator
B2: Parameters | H2: Income Performance
B3: Year of Birth | F3: 1969
B4: Start Draw-down In | F4: 2026
B5: End Draw-down By | F5: 2058
B6: Private Pension Eligible Year (age 55) | F6: =F3+55 -> 2024
B7: State Pension Eligible Year | F7: =F3+67 -> 2036
B8: Final Year Percentage (keep hidden)
B9: First Year Estimated Income | C9: Net | D9: ='Person 2 Draw-down'!G32 -> 18924.1 | E9: | Gross | F9: 18924.1
B10: Estimated Income @ 70 | C10: Net Real | D10: ='Person 2 Draw-down'!S27*$D$9 -> 30366.115 | E10: | Nominal Gross | F10: ='Person 2 Draw-down'!S24 -> 41860.025 | I10: =Income!$K$4 -> 0
B11: Estimated Income @ 80 | C11: Net Real | D11: ='Person 2 Draw-down'!AC27*$D$9 -> 29147.585 | E11: | Nominal Gross | F11: ='Person 2 Draw-down'!AC24 -> 51434.139 | I11: =I10 -> 0
B12: Final Year Estimated Income | C12: Net Real | D12: ='Person 2 Draw-down'!AJ27*$D$9 -> 28965.598 | E12: | Nominal Gross | F12: ='Person 2 Draw-down'!AJ24 -> 60757.298
B13: Final Year SIPP Balance Target | F13: 0
B14: Final Year SIPP Balance | F14: ='Person 2 Draw-down'!AJ6
B16: Optional annual spending reduction from age 70 | F16: 0.2
B17: Optional annual spending reduction from age 80 | F17: 0.4
B18: Inflation | F18: 0.025
B19: State Pension Growth (triple-lock) | F19: 0.04
B20: Inflation tracking mode | F20: Smooth
A50: Age | B50: ISA | C50: Rent | D50: State Pension | E50: Annuities | F50: DB Pensions | G50: Cash | H50: Total Annual Income | I50: Inflation | J50: Tax | K50: Total Net Income
A51: 57 | B51: 7086.61 | C51: 0 | D51: 0 | E51: 0 | F51: 7000 | G51: 4837.49 | H51: 18924.1 | I51: 18924.1 | J51: 0 | K51: 18924.1
A52: 58 | B52: 7086.61 | C52: 0 | D52: 0 | E52: 0 | F52: 7000 | G52: 4837.49 | H52: 18924.1 | I52: 19397.202 | J52: 0 | K52: 18924.1
A53: 59 | B53: 7086.61 | C53: 0 | D53: 0 | E53: 0 | F53: 7000 | G53: 4837.49 | H53: 18924.1 | I53: 19882.133 | J53: 0 | K53: 18924.1
A54: 60 | B54: 7086.61 | C54: 0 | D54: 0 | E54: 0 | F54: 7000 | G54: 4837.49 | H54: 18924.1 | I54: 20379.186 | J54: 0 | K54: 18924.1
A55: 61 | B55: 7086.61 | C55: 0 | D55: 0 | E55: 0 | F55: 10000 | G55: 4837.49 | H55: 21924.1 | I55: 20888.666 | J55: 453.498 | K55: 21470.602
A56: 62 | B56: 7086.61 | C56: 0 | D56: 0 | E56: 0 | F56: 10000 | G56: 4837.49 | H56: 21924.1 | I56: 21410.882 | J56: 453.498 | K56: 21470.602
A57: 63 | B57: 7086.61 | C57: 0 | D57: 0 | E57: 0 | F57: 10000 | G57: 4837.49 | H57: 21924.1 | I57: 21946.154 | J57: 453.498 | K57: 21470.602
A58: 64 | B58: 7086.61 | C58: 0 | D58: 0 | E58: 0 | F58: 10000 | G58: 4837.49 | H58: 21924.1 | I58: 22494.808 | J58: 453.498 | K58: 21470.602
A59: 65 | B59: 7086.61 | C59: 0 | D59: 0 | E59: 0 | F59: 10000 | G59: 4837.49 | H59: 21924.1 | I59: 23057.178 | J59: 453.498 | K59: 21470.602
A60: 66 | B60: 7086.61 | C60: 0 | D60: 0 | E60: 0 | F60: 10000 | G60: 4837.49 | H60: 21924.1 | I60: 23633.608 | J60: 453.498 | K60: 21470.602
A61: 67 | B61: 7086.61 | C61: 0 | D61: 17722.965 | E61: 0 | F61: 10000 | G61: 4837.49 | H61: 39647.065 | I61: 24224.448 | J61: 3998.091 | K61: 35648.974
A62: 68 | B62: 7086.61 | C62: 0 | D62: 18431.883 | E62: 0 | F62: 10000 | G62: 4837.49 | H62: 40355.983 | I62: 24830.059 | J62: 4139.8747 | K62: 36216.109
... A83: 88 | B83: 22155.433 | C83: 0 | D83: 40386.526 | E83: 0 | F83: 10000 | G83: 9373.5066 | H83: 81915.466 | I83: 69482.12 | J83: 9438.0066 | K83: 72477.46
A84: 89 | B84: 40904.285 | C84: 133483.49 | D84: 136307.91 | E84: 21981.05 | F84: 111502.44 | G84: 6497.4927 | H84: 68344.104 | I84: 0.14753686 | J84: 4855.0691
A85: 90 | B85: 44415.693 | C85: 139715.61 | D85: 139715.61 | E85: 23227.474 | F85: 116488.14 | G85: 6497.4927 | H85: 70203.659 | I85: 0.1489265 | J85: 4979.0395
A86: 90 | B86: 18838.554 | C86: 118396.24 | D86: 147995.3 | E86: 18080.228 | F86: 100316.01

Sheet Person 2 Draw-down
A1: Pension 2 Draw-down
